2025-04-01 19:23:54 - bot - INFO - Starting Token Security Bot...
2025-04-01 19:31:48 - bot - INFO - Starting Token Security Bot...
2025-04-01 19:32:00 - bot - INFO - Bot stopped by user
2025-04-01 19:36:53 - bot - INFO - Starting Token Security Bot...
2025-04-01 19:42:20 - bot - INFO - Starting Token Security Bot...
2025-04-01 21:29:51 - bot - ERROR - Fatal error: Timed out
Traceback (most recent call last):
  File "C:\Users\Admin\AppData\Local\Programs\Python\Python311\Lib\site-packages\anyio\streams\tls.py", line 140, in _call_sslobject_method
    result = func(*args)
             ^^^^^^^^^^^
  File "C:\Users\Admin\AppData\Local\Programs\Python\Python311\Lib\ssl.py", line 921, in read
    v = self._sslobj.read(len)
        ^^^^^^^^^^^^^^^^^^^^^^
ssl.SSLWantReadError: The operation did not complete (read) (_ssl.c:2580)

During handling of the above exception, another exception occurred:

Traceback (most recent call last):
  File "C:\Users\Admin\AppData\Local\Programs\Python\Python311\Lib\site-packages\anyio\_core\_tasks.py", line 115, in fail_after
    yield cancel_scope
  File "C:\Users\Admin\AppData\Local\Programs\Python\Python311\Lib\site-packages\httpcore\_backends\anyio.py", line 34, in read
    return await self._stream.receive(max_bytes=max_bytes)
           ^^^^^^^^^^^^^^^^^^^^^^^^^^^^^^^^^^^^^^^^^^^^^^^
  File "C:\Users\Admin\AppData\Local\Programs\Python\Python311\Lib\site-packages\anyio\streams\tls.py", line 204, in receive
    data = await self._call_sslobject_method(self._ssl_object.read, max_bytes)
           ^^^^^^^^^^^^^^^^^^^^^^^^^^^^^^^^^^^^^^^^^^^^^^^^^^^^^^^^^^^^^^^^^^^
  File "C:\Users\Admin\AppData\Local\Programs\Python\Python311\Lib\site-packages\anyio\streams\tls.py", line 147, in _call_sslobject_method
    data = await self.transport_stream.receive()
           ^^^^^^^^^^^^^^^^^^^^^^^^^^^^^^^^^^^^^
  File "C:\Users\Admin\AppData\Local\Programs\Python\Python311\Lib\site-packages\anyio\_backends\_asyncio.py", line 1246, in receive
    await self._protocol.read_event.wait()
  File "C:\Users\Admin\AppData\Local\Programs\Python\Python311\Lib\asyncio\locks.py", line 213, in wait
    await fut
asyncio.exceptions.CancelledError: Cancelled by cancel scope 18529921390

During handling of the above exception, another exception occurred:

Traceback (most recent call last):
  File "C:\Users\Admin\AppData\Local\Programs\Python\Python311\Lib\site-packages\httpcore\_exceptions.py", line 10, in map_exceptions
    yield
  File "C:\Users\Admin\AppData\Local\Programs\Python\Python311\Lib\site-packages\httpcore\_backends\anyio.py", line 32, in read
    with anyio.fail_after(timeout):
  File "C:\Users\Admin\AppData\Local\Programs\Python\Python311\Lib\contextlib.py", line 158, in __exit__
    self.gen.throw(typ, value, traceback)
  File "C:\Users\Admin\AppData\Local\Programs\Python\Python311\Lib\site-packages\anyio\_core\_tasks.py", line 118, in fail_after
    raise TimeoutError
TimeoutError

The above exception was the direct cause of the following exception:

Traceback (most recent call last):
  File "C:\Users\Admin\AppData\Local\Programs\Python\Python311\Lib\site-packages\httpx\_transports\default.py", line 60, in map_httpcore_exceptions
    yield
  File "C:\Users\Admin\AppData\Local\Programs\Python\Python311\Lib\site-packages\httpx\_transports\default.py", line 353, in handle_async_request
    resp = await self._pool.handle_async_request(req)
           ^^^^^^^^^^^^^^^^^^^^^^^^^^^^^^^^^^^^^^^^^^
  File "C:\Users\Admin\AppData\Local\Programs\Python\Python311\Lib\site-packages\httpcore\_async\connection_pool.py", line 262, in handle_async_request
    raise exc
  File "C:\Users\Admin\AppData\Local\Programs\Python\Python311\Lib\site-packages\httpcore\_async\connection_pool.py", line 245, in handle_async_request
    response = await connection.handle_async_request(request)
               ^^^^^^^^^^^^^^^^^^^^^^^^^^^^^^^^^^^^^^^^^^^^^^
  File "C:\Users\Admin\AppData\Local\Programs\Python\Python311\Lib\site-packages\httpcore\_async\connection.py", line 96, in handle_async_request
    return await self._connection.handle_async_request(request)
           ^^^^^^^^^^^^^^^^^^^^^^^^^^^^^^^^^^^^^^^^^^^^^^^^^^^^
  File "C:\Users\Admin\AppData\Local\Programs\Python\Python311\Lib\site-packages\httpcore\_async\http11.py", line 121, in handle_async_request
    raise exc
  File "C:\Users\Admin\AppData\Local\Programs\Python\Python311\Lib\site-packages\httpcore\_async\http11.py", line 99, in handle_async_request
    ) = await self._receive_response_headers(**kwargs)
        ^^^^^^^^^^^^^^^^^^^^^^^^^^^^^^^^^^^^^^^^^^^^^^
  File "C:\Users\Admin\AppData\Local\Programs\Python\Python311\Lib\site-packages\httpcore\_async\http11.py", line 164, in _receive_response_headers
    event = await self._receive_event(timeout=timeout)
            ^^^^^^^^^^^^^^^^^^^^^^^^^^^^^^^^^^^^^^^^^^
  File "C:\Users\Admin\AppData\Local\Programs\Python\Python311\Lib\site-packages\httpcore\_async\http11.py", line 200, in _receive_event
    data = await self._network_stream.read(
           ^^^^^^^^^^^^^^^^^^^^^^^^^^^^^^^^
  File "C:\Users\Admin\AppData\Local\Programs\Python\Python311\Lib\site-packages\httpcore\_backends\anyio.py", line 31, in read
    with map_exceptions(exc_map):
  File "C:\Users\Admin\AppData\Local\Programs\Python\Python311\Lib\contextlib.py", line 158, in __exit__
    self.gen.throw(typ, value, traceback)
  File "C:\Users\Admin\AppData\Local\Programs\Python\Python311\Lib\site-packages\httpcore\_exceptions.py", line 14, in map_exceptions
    raise to_exc(exc) from exc
httpcore.ReadTimeout

The above exception was the direct cause of the following exception:

Traceback (most recent call last):
  File "C:\Users\Admin\AppData\Local\Programs\Python\Python311\Lib\site-packages\telegram\request\_httpxrequest.py", line 219, in do_request
    res = await self._client.request(
          ^^^^^^^^^^^^^^^^^^^^^^^^^^^
  File "C:\Users\Admin\AppData\Local\Programs\Python\Python311\Lib\site-packages\httpx\_client.py", line 1530, in request
    return await self.send(request, auth=auth, follow_redirects=follow_redirects)
           ^^^^^^^^^^^^^^^^^^^^^^^^^^^^^^^^^^^^^^^^^^^^^^^^^^^^^^^^^^^^^^^^^^^^^^
  File "C:\Users\Admin\AppData\Local\Programs\Python\Python311\Lib\site-packages\httpx\_client.py", line 1617, in send
    response = await self._send_handling_auth(
               ^^^^^^^^^^^^^^^^^^^^^^^^^^^^^^^
  File "C:\Users\Admin\AppData\Local\Programs\Python\Python311\Lib\site-packages\httpx\_client.py", line 1645, in _send_handling_auth
    response = await self._send_handling_redirects(
               ^^^^^^^^^^^^^^^^^^^^^^^^^^^^^^^^^^^^
  File "C:\Users\Admin\AppData\Local\Programs\Python\Python311\Lib\site-packages\httpx\_client.py", line 1682, in _send_handling_redirects
    response = await self._send_single_request(request)
               ^^^^^^^^^^^^^^^^^^^^^^^^^^^^^^^^^^^^^^^^
  File "C:\Users\Admin\AppData\Local\Programs\Python\Python311\Lib\site-packages\httpx\_client.py", line 1719, in _send_single_request
    response = await transport.handle_async_request(request)
               ^^^^^^^^^^^^^^^^^^^^^^^^^^^^^^^^^^^^^^^^^^^^^
  File "C:\Users\Admin\AppData\Local\Programs\Python\Python311\Lib\site-packages\httpx\_transports\default.py", line 352, in handle_async_request
    with map_httpcore_exceptions():
  File "C:\Users\Admin\AppData\Local\Programs\Python\Python311\Lib\contextlib.py", line 158, in __exit__
    self.gen.throw(typ, value, traceback)
  File "C:\Users\Admin\AppData\Local\Programs\Python\Python311\Lib\site-packages\httpx\_transports\default.py", line 77, in map_httpcore_exceptions
    raise mapped_exc(message) from exc
httpx.ReadTimeout

The above exception was the direct cause of the following exception:

Traceback (most recent call last):
  File "F:\Crypto\Safe_Token_Bot\app\main.py", line 42, in main
    bot.run()
  File "F:\Crypto\Safe_Token_Bot\app\core\bot.py", line 567, in run
    self.application.run_polling(allowed_updates=Update.ALL_TYPES)
  File "C:\Users\Admin\AppData\Local\Programs\Python\Python311\Lib\site-packages\telegram\ext\_application.py", line 765, in run_polling
    return self.__run(
           ^^^^^^^^^^^
  File "C:\Users\Admin\AppData\Local\Programs\Python\Python311\Lib\site-packages\telegram\ext\_application.py", line 963, in __run
    loop.run_until_complete(self.updater.stop())  # type: ignore[union-attr]
    ^^^^^^^^^^^^^^^^^^^^^^^^^^^^^^^^^^^^^^^^^^^^
  File "C:\Users\Admin\AppData\Local\Programs\Python\Python311\Lib\asyncio\base_events.py", line 654, in run_until_complete
    return future.result()
           ^^^^^^^^^^^^^^^
  File "C:\Users\Admin\AppData\Local\Programs\Python\Python311\Lib\site-packages\telegram\ext\_updater.py", line 752, in stop
    await self._stop_polling()
  File "C:\Users\Admin\AppData\Local\Programs\Python\Python311\Lib\site-packages\telegram\ext\_updater.py", line 777, in _stop_polling
    await self.__polling_cleanup_cb()
  File "C:\Users\Admin\AppData\Local\Programs\Python\Python311\Lib\site-packages\telegram\ext\_updater.py", line 381, in _get_updates_cleanup
    await self.bot.get_updates(
  File "C:\Users\Admin\AppData\Local\Programs\Python\Python311\Lib\site-packages\telegram\ext\_extbot.py", line 553, in get_updates
    updates = await super().get_updates(
              ^^^^^^^^^^^^^^^^^^^^^^^^^^
  File "C:\Users\Admin\AppData\Local\Programs\Python\Python311\Lib\site-packages\telegram\_bot.py", line 394, in decorator
    result = await func(self, *args, **kwargs)  # skipcq: PYL-E1102
             ^^^^^^^^^^^^^^^^^^^^^^^^^^^^^^^^^
  File "C:\Users\Admin\AppData\Local\Programs\Python\Python311\Lib\site-packages\telegram\_bot.py", line 3542, in get_updates
    await self._post(
  File "C:\Users\Admin\AppData\Local\Programs\Python\Python311\Lib\site-packages\telegram\_bot.py", line 482, in _post
    return await self._do_post(
           ^^^^^^^^^^^^^^^^^^^^
  File "C:\Users\Admin\AppData\Local\Programs\Python\Python311\Lib\site-packages\telegram\ext\_extbot.py", line 335, in _do_post
    return await super()._do_post(
           ^^^^^^^^^^^^^^^^^^^^^^^
  File "C:\Users\Admin\AppData\Local\Programs\Python\Python311\Lib\site-packages\telegram\_bot.py", line 510, in _do_post
    return await request.post(
           ^^^^^^^^^^^^^^^^^^^
  File "C:\Users\Admin\AppData\Local\Programs\Python\Python311\Lib\site-packages\telegram\request\_baserequest.py", line 168, in post
    result = await self._request_wrapper(
             ^^^^^^^^^^^^^^^^^^^^^^^^^^^^
  File "C:\Users\Admin\AppData\Local\Programs\Python\Python311\Lib\site-packages\telegram\request\_baserequest.py", line 288, in _request_wrapper
    raise exc
  File "C:\Users\Admin\AppData\Local\Programs\Python\Python311\Lib\site-packages\telegram\request\_baserequest.py", line 278, in _request_wrapper
    code, payload = await self.do_request(
                    ^^^^^^^^^^^^^^^^^^^^^^
  File "C:\Users\Admin\AppData\Local\Programs\Python\Python311\Lib\site-packages\telegram\request\_httpxrequest.py", line 236, in do_request
    raise TimedOut from err
telegram.error.TimedOut: Timed out
2025-04-01 21:37:15 - bot - INFO - Starting Token Security Bot...
2025-04-01 21:50:08 - bot - INFO - Starting Token Security Bot...
2025-04-01 21:52:43 - bot - ERROR - Fatal error: Timed out
Traceback (most recent call last):
  File "C:\Users\Admin\AppData\Local\Programs\Python\Python311\Lib\site-packages\anyio\streams\tls.py", line 140, in _call_sslobject_method
    result = func(*args)
             ^^^^^^^^^^^
  File "C:\Users\Admin\AppData\Local\Programs\Python\Python311\Lib\ssl.py", line 921, in read
    v = self._sslobj.read(len)
        ^^^^^^^^^^^^^^^^^^^^^^
ssl.SSLWantReadError: The operation did not complete (read) (_ssl.c:2580)

During handling of the above exception, another exception occurred:

Traceback (most recent call last):
  File "C:\Users\Admin\AppData\Local\Programs\Python\Python311\Lib\site-packages\anyio\_core\_tasks.py", line 115, in fail_after
    yield cancel_scope
  File "C:\Users\Admin\AppData\Local\Programs\Python\Python311\Lib\site-packages\httpcore\_backends\anyio.py", line 34, in read
    return await self._stream.receive(max_bytes=max_bytes)
           ^^^^^^^^^^^^^^^^^^^^^^^^^^^^^^^^^^^^^^^^^^^^^^^
  File "C:\Users\Admin\AppData\Local\Programs\Python\Python311\Lib\site-packages\anyio\streams\tls.py", line 204, in receive
    data = await self._call_sslobject_method(self._ssl_object.read, max_bytes)
           ^^^^^^^^^^^^^^^^^^^^^^^^^^^^^^^^^^^^^^^^^^^^^^^^^^^^^^^^^^^^^^^^^^^
  File "C:\Users\Admin\AppData\Local\Programs\Python\Python311\Lib\site-packages\anyio\streams\tls.py", line 147, in _call_sslobject_method
    data = await self.transport_stream.receive()
           ^^^^^^^^^^^^^^^^^^^^^^^^^^^^^^^^^^^^^
  File "C:\Users\Admin\AppData\Local\Programs\Python\Python311\Lib\site-packages\anyio\_backends\_asyncio.py", line 1246, in receive
    await self._protocol.read_event.wait()
  File "C:\Users\Admin\AppData\Local\Programs\Python\Python311\Lib\asyncio\locks.py", line 213, in wait
    await fut
asyncio.exceptions.CancelledError: Cancelled by cancel scope 241754c1550

During handling of the above exception, another exception occurred:

Traceback (most recent call last):
  File "C:\Users\Admin\AppData\Local\Programs\Python\Python311\Lib\site-packages\httpcore\_exceptions.py", line 10, in map_exceptions
    yield
  File "C:\Users\Admin\AppData\Local\Programs\Python\Python311\Lib\site-packages\httpcore\_backends\anyio.py", line 32, in read
    with anyio.fail_after(timeout):
  File "C:\Users\Admin\AppData\Local\Programs\Python\Python311\Lib\contextlib.py", line 158, in __exit__
    self.gen.throw(typ, value, traceback)
  File "C:\Users\Admin\AppData\Local\Programs\Python\Python311\Lib\site-packages\anyio\_core\_tasks.py", line 118, in fail_after
    raise TimeoutError
TimeoutError

The above exception was the direct cause of the following exception:

Traceback (most recent call last):
  File "C:\Users\Admin\AppData\Local\Programs\Python\Python311\Lib\site-packages\httpx\_transports\default.py", line 60, in map_httpcore_exceptions
    yield
  File "C:\Users\Admin\AppData\Local\Programs\Python\Python311\Lib\site-packages\httpx\_transports\default.py", line 353, in handle_async_request
    resp = await self._pool.handle_async_request(req)
           ^^^^^^^^^^^^^^^^^^^^^^^^^^^^^^^^^^^^^^^^^^
  File "C:\Users\Admin\AppData\Local\Programs\Python\Python311\Lib\site-packages\httpcore\_async\connection_pool.py", line 262, in handle_async_request
    raise exc
  File "C:\Users\Admin\AppData\Local\Programs\Python\Python311\Lib\site-packages\httpcore\_async\connection_pool.py", line 245, in handle_async_request
    response = await connection.handle_async_request(request)
               ^^^^^^^^^^^^^^^^^^^^^^^^^^^^^^^^^^^^^^^^^^^^^^
  File "C:\Users\Admin\AppData\Local\Programs\Python\Python311\Lib\site-packages\httpcore\_async\connection.py", line 96, in handle_async_request
    return await self._connection.handle_async_request(request)
           ^^^^^^^^^^^^^^^^^^^^^^^^^^^^^^^^^^^^^^^^^^^^^^^^^^^^
  File "C:\Users\Admin\AppData\Local\Programs\Python\Python311\Lib\site-packages\httpcore\_async\http11.py", line 121, in handle_async_request
    raise exc
  File "C:\Users\Admin\AppData\Local\Programs\Python\Python311\Lib\site-packages\httpcore\_async\http11.py", line 99, in handle_async_request
    ) = await self._receive_response_headers(**kwargs)
        ^^^^^^^^^^^^^^^^^^^^^^^^^^^^^^^^^^^^^^^^^^^^^^
  File "C:\Users\Admin\AppData\Local\Programs\Python\Python311\Lib\site-packages\httpcore\_async\http11.py", line 164, in _receive_response_headers
    event = await self._receive_event(timeout=timeout)
            ^^^^^^^^^^^^^^^^^^^^^^^^^^^^^^^^^^^^^^^^^^
  File "C:\Users\Admin\AppData\Local\Programs\Python\Python311\Lib\site-packages\httpcore\_async\http11.py", line 200, in _receive_event
    data = await self._network_stream.read(
           ^^^^^^^^^^^^^^^^^^^^^^^^^^^^^^^^
  File "C:\Users\Admin\AppData\Local\Programs\Python\Python311\Lib\site-packages\httpcore\_backends\anyio.py", line 31, in read
    with map_exceptions(exc_map):
  File "C:\Users\Admin\AppData\Local\Programs\Python\Python311\Lib\contextlib.py", line 158, in __exit__
    self.gen.throw(typ, value, traceback)
  File "C:\Users\Admin\AppData\Local\Programs\Python\Python311\Lib\site-packages\httpcore\_exceptions.py", line 14, in map_exceptions
    raise to_exc(exc) from exc
httpcore.ReadTimeout

The above exception was the direct cause of the following exception:

Traceback (most recent call last):
  File "C:\Users\Admin\AppData\Local\Programs\Python\Python311\Lib\site-packages\telegram\request\_httpxrequest.py", line 219, in do_request
    res = await self._client.request(
          ^^^^^^^^^^^^^^^^^^^^^^^^^^^
  File "C:\Users\Admin\AppData\Local\Programs\Python\Python311\Lib\site-packages\httpx\_client.py", line 1530, in request
    return await self.send(request, auth=auth, follow_redirects=follow_redirects)
           ^^^^^^^^^^^^^^^^^^^^^^^^^^^^^^^^^^^^^^^^^^^^^^^^^^^^^^^^^^^^^^^^^^^^^^
  File "C:\Users\Admin\AppData\Local\Programs\Python\Python311\Lib\site-packages\httpx\_client.py", line 1617, in send
    response = await self._send_handling_auth(
               ^^^^^^^^^^^^^^^^^^^^^^^^^^^^^^^
  File "C:\Users\Admin\AppData\Local\Programs\Python\Python311\Lib\site-packages\httpx\_client.py", line 1645, in _send_handling_auth
    response = await self._send_handling_redirects(
               ^^^^^^^^^^^^^^^^^^^^^^^^^^^^^^^^^^^^
  File "C:\Users\Admin\AppData\Local\Programs\Python\Python311\Lib\site-packages\httpx\_client.py", line 1682, in _send_handling_redirects
    response = await self._send_single_request(request)
               ^^^^^^^^^^^^^^^^^^^^^^^^^^^^^^^^^^^^^^^^
  File "C:\Users\Admin\AppData\Local\Programs\Python\Python311\Lib\site-packages\httpx\_client.py", line 1719, in _send_single_request
    response = await transport.handle_async_request(request)
               ^^^^^^^^^^^^^^^^^^^^^^^^^^^^^^^^^^^^^^^^^^^^^
  File "C:\Users\Admin\AppData\Local\Programs\Python\Python311\Lib\site-packages\httpx\_transports\default.py", line 352, in handle_async_request
    with map_httpcore_exceptions():
  File "C:\Users\Admin\AppData\Local\Programs\Python\Python311\Lib\contextlib.py", line 158, in __exit__
    self.gen.throw(typ, value, traceback)
  File "C:\Users\Admin\AppData\Local\Programs\Python\Python311\Lib\site-packages\httpx\_transports\default.py", line 77, in map_httpcore_exceptions
    raise mapped_exc(message) from exc
httpx.ReadTimeout

The above exception was the direct cause of the following exception:

Traceback (most recent call last):
  File "F:\Crypto\Safe_Token_Bot\app\main.py", line 42, in main
    bot.run()
  File "F:\Crypto\Safe_Token_Bot\app\core\bot.py", line 567, in run
    self.application.run_polling(allowed_updates=Update.ALL_TYPES)
  File "C:\Users\Admin\AppData\Local\Programs\Python\Python311\Lib\site-packages\telegram\ext\_application.py", line 765, in run_polling
    return self.__run(
           ^^^^^^^^^^^
  File "C:\Users\Admin\AppData\Local\Programs\Python\Python311\Lib\site-packages\telegram\ext\_application.py", line 963, in __run
    loop.run_until_complete(self.updater.stop())  # type: ignore[union-attr]
    ^^^^^^^^^^^^^^^^^^^^^^^^^^^^^^^^^^^^^^^^^^^^
  File "C:\Users\Admin\AppData\Local\Programs\Python\Python311\Lib\asyncio\base_events.py", line 654, in run_until_complete
    return future.result()
           ^^^^^^^^^^^^^^^
  File "C:\Users\Admin\AppData\Local\Programs\Python\Python311\Lib\site-packages\telegram\ext\_updater.py", line 752, in stop
    await self._stop_polling()
  File "C:\Users\Admin\AppData\Local\Programs\Python\Python311\Lib\site-packages\telegram\ext\_updater.py", line 777, in _stop_polling
    await self.__polling_cleanup_cb()
  File "C:\Users\Admin\AppData\Local\Programs\Python\Python311\Lib\site-packages\telegram\ext\_updater.py", line 381, in _get_updates_cleanup
    await self.bot.get_updates(
  File "C:\Users\Admin\AppData\Local\Programs\Python\Python311\Lib\site-packages\telegram\ext\_extbot.py", line 553, in get_updates
    updates = await super().get_updates(
              ^^^^^^^^^^^^^^^^^^^^^^^^^^
  File "C:\Users\Admin\AppData\Local\Programs\Python\Python311\Lib\site-packages\telegram\_bot.py", line 394, in decorator
    result = await func(self, *args, **kwargs)  # skipcq: PYL-E1102
             ^^^^^^^^^^^^^^^^^^^^^^^^^^^^^^^^^
  File "C:\Users\Admin\AppData\Local\Programs\Python\Python311\Lib\site-packages\telegram\_bot.py", line 3542, in get_updates
    await self._post(
  File "C:\Users\Admin\AppData\Local\Programs\Python\Python311\Lib\site-packages\telegram\_bot.py", line 482, in _post
    return await self._do_post(
           ^^^^^^^^^^^^^^^^^^^^
  File "C:\Users\Admin\AppData\Local\Programs\Python\Python311\Lib\site-packages\telegram\ext\_extbot.py", line 335, in _do_post
    return await super()._do_post(
           ^^^^^^^^^^^^^^^^^^^^^^^
  File "C:\Users\Admin\AppData\Local\Programs\Python\Python311\Lib\site-packages\telegram\_bot.py", line 510, in _do_post
    return await request.post(
           ^^^^^^^^^^^^^^^^^^^
  File "C:\Users\Admin\AppData\Local\Programs\Python\Python311\Lib\site-packages\telegram\request\_baserequest.py", line 168, in post
    result = await self._request_wrapper(
             ^^^^^^^^^^^^^^^^^^^^^^^^^^^^
  File "C:\Users\Admin\AppData\Local\Programs\Python\Python311\Lib\site-packages\telegram\request\_baserequest.py", line 288, in _request_wrapper
    raise exc
  File "C:\Users\Admin\AppData\Local\Programs\Python\Python311\Lib\site-packages\telegram\request\_baserequest.py", line 278, in _request_wrapper
    code, payload = await self.do_request(
                    ^^^^^^^^^^^^^^^^^^^^^^
  File "C:\Users\Admin\AppData\Local\Programs\Python\Python311\Lib\site-packages\telegram\request\_httpxrequest.py", line 236, in do_request
    raise TimedOut from err
telegram.error.TimedOut: Timed out
2025-04-01 21:53:53 - bot - INFO - Starting Token Security Bot...
2025-04-01 21:58:27 - bot - INFO - Starting Token Security Bot...
2025-04-01 22:07:49 - bot - INFO - Starting Token Security Bot...
2025-04-01 22:13:59 - bot - INFO - Starting Token Security Bot...
2025-04-01 22:17:43 - bot - INFO - Starting Token Security Bot...
2025-04-01 22:21:41 - bot - INFO - Starting Token Security Bot...
2025-04-01 22:23:09 - bot - ERROR - Fatal error: Timed out
Traceback (most recent call last):
  File "C:\Users\Admin\AppData\Local\Programs\Python\Python311\Lib\site-packages\anyio\streams\tls.py", line 140, in _call_sslobject_method
    result = func(*args)
             ^^^^^^^^^^^
  File "C:\Users\Admin\AppData\Local\Programs\Python\Python311\Lib\ssl.py", line 921, in read
    v = self._sslobj.read(len)
        ^^^^^^^^^^^^^^^^^^^^^^
ssl.SSLWantReadError: The operation did not complete (read) (_ssl.c:2580)

During handling of the above exception, another exception occurred:

Traceback (most recent call last):
  File "C:\Users\Admin\AppData\Local\Programs\Python\Python311\Lib\site-packages\anyio\_core\_tasks.py", line 115, in fail_after
    yield cancel_scope
  File "C:\Users\Admin\AppData\Local\Programs\Python\Python311\Lib\site-packages\httpcore\_backends\anyio.py", line 34, in read
    return await self._stream.receive(max_bytes=max_bytes)
           ^^^^^^^^^^^^^^^^^^^^^^^^^^^^^^^^^^^^^^^^^^^^^^^
  File "C:\Users\Admin\AppData\Local\Programs\Python\Python311\Lib\site-packages\anyio\streams\tls.py", line 204, in receive
    data = await self._call_sslobject_method(self._ssl_object.read, max_bytes)
           ^^^^^^^^^^^^^^^^^^^^^^^^^^^^^^^^^^^^^^^^^^^^^^^^^^^^^^^^^^^^^^^^^^^
  File "C:\Users\Admin\AppData\Local\Programs\Python\Python311\Lib\site-packages\anyio\streams\tls.py", line 147, in _call_sslobject_method
    data = await self.transport_stream.receive()
           ^^^^^^^^^^^^^^^^^^^^^^^^^^^^^^^^^^^^^
  File "C:\Users\Admin\AppData\Local\Programs\Python\Python311\Lib\site-packages\anyio\_backends\_asyncio.py", line 1246, in receive
    await self._protocol.read_event.wait()
  File "C:\Users\Admin\AppData\Local\Programs\Python\Python311\Lib\asyncio\locks.py", line 213, in wait
    await fut
asyncio.exceptions.CancelledError: Cancelled by cancel scope 1ebb141a310

During handling of the above exception, another exception occurred:

Traceback (most recent call last):
  File "C:\Users\Admin\AppData\Local\Programs\Python\Python311\Lib\site-packages\httpcore\_exceptions.py", line 10, in map_exceptions
    yield
  File "C:\Users\Admin\AppData\Local\Programs\Python\Python311\Lib\site-packages\httpcore\_backends\anyio.py", line 32, in read
    with anyio.fail_after(timeout):
  File "C:\Users\Admin\AppData\Local\Programs\Python\Python311\Lib\contextlib.py", line 158, in __exit__
    self.gen.throw(typ, value, traceback)
  File "C:\Users\Admin\AppData\Local\Programs\Python\Python311\Lib\site-packages\anyio\_core\_tasks.py", line 118, in fail_after
    raise TimeoutError
TimeoutError

The above exception was the direct cause of the following exception:

Traceback (most recent call last):
  File "C:\Users\Admin\AppData\Local\Programs\Python\Python311\Lib\site-packages\httpx\_transports\default.py", line 60, in map_httpcore_exceptions
    yield
  File "C:\Users\Admin\AppData\Local\Programs\Python\Python311\Lib\site-packages\httpx\_transports\default.py", line 353, in handle_async_request
    resp = await self._pool.handle_async_request(req)
           ^^^^^^^^^^^^^^^^^^^^^^^^^^^^^^^^^^^^^^^^^^
  File "C:\Users\Admin\AppData\Local\Programs\Python\Python311\Lib\site-packages\httpcore\_async\connection_pool.py", line 262, in handle_async_request
    raise exc
  File "C:\Users\Admin\AppData\Local\Programs\Python\Python311\Lib\site-packages\httpcore\_async\connection_pool.py", line 245, in handle_async_request
    response = await connection.handle_async_request(request)
               ^^^^^^^^^^^^^^^^^^^^^^^^^^^^^^^^^^^^^^^^^^^^^^
  File "C:\Users\Admin\AppData\Local\Programs\Python\Python311\Lib\site-packages\httpcore\_async\connection.py", line 96, in handle_async_request
    return await self._connection.handle_async_request(request)
           ^^^^^^^^^^^^^^^^^^^^^^^^^^^^^^^^^^^^^^^^^^^^^^^^^^^^
  File "C:\Users\Admin\AppData\Local\Programs\Python\Python311\Lib\site-packages\httpcore\_async\http11.py", line 121, in handle_async_request
    raise exc
  File "C:\Users\Admin\AppData\Local\Programs\Python\Python311\Lib\site-packages\httpcore\_async\http11.py", line 99, in handle_async_request
    ) = await self._receive_response_headers(**kwargs)
        ^^^^^^^^^^^^^^^^^^^^^^^^^^^^^^^^^^^^^^^^^^^^^^
  File "C:\Users\Admin\AppData\Local\Programs\Python\Python311\Lib\site-packages\httpcore\_async\http11.py", line 164, in _receive_response_headers
    event = await self._receive_event(timeout=timeout)
            ^^^^^^^^^^^^^^^^^^^^^^^^^^^^^^^^^^^^^^^^^^
  File "C:\Users\Admin\AppData\Local\Programs\Python\Python311\Lib\site-packages\httpcore\_async\http11.py", line 200, in _receive_event
    data = await self._network_stream.read(
           ^^^^^^^^^^^^^^^^^^^^^^^^^^^^^^^^
  File "C:\Users\Admin\AppData\Local\Programs\Python\Python311\Lib\site-packages\httpcore\_backends\anyio.py", line 31, in read
    with map_exceptions(exc_map):
  File "C:\Users\Admin\AppData\Local\Programs\Python\Python311\Lib\contextlib.py", line 158, in __exit__
    self.gen.throw(typ, value, traceback)
  File "C:\Users\Admin\AppData\Local\Programs\Python\Python311\Lib\site-packages\httpcore\_exceptions.py", line 14, in map_exceptions
    raise to_exc(exc) from exc
httpcore.ReadTimeout

The above exception was the direct cause of the following exception:

Traceback (most recent call last):
  File "C:\Users\Admin\AppData\Local\Programs\Python\Python311\Lib\site-packages\telegram\request\_httpxrequest.py", line 219, in do_request
    res = await self._client.request(
          ^^^^^^^^^^^^^^^^^^^^^^^^^^^
  File "C:\Users\Admin\AppData\Local\Programs\Python\Python311\Lib\site-packages\httpx\_client.py", line 1530, in request
    return await self.send(request, auth=auth, follow_redirects=follow_redirects)
           ^^^^^^^^^^^^^^^^^^^^^^^^^^^^^^^^^^^^^^^^^^^^^^^^^^^^^^^^^^^^^^^^^^^^^^
  File "C:\Users\Admin\AppData\Local\Programs\Python\Python311\Lib\site-packages\httpx\_client.py", line 1617, in send
    response = await self._send_handling_auth(
               ^^^^^^^^^^^^^^^^^^^^^^^^^^^^^^^
  File "C:\Users\Admin\AppData\Local\Programs\Python\Python311\Lib\site-packages\httpx\_client.py", line 1645, in _send_handling_auth
    response = await self._send_handling_redirects(
               ^^^^^^^^^^^^^^^^^^^^^^^^^^^^^^^^^^^^
  File "C:\Users\Admin\AppData\Local\Programs\Python\Python311\Lib\site-packages\httpx\_client.py", line 1682, in _send_handling_redirects
    response = await self._send_single_request(request)
               ^^^^^^^^^^^^^^^^^^^^^^^^^^^^^^^^^^^^^^^^
  File "C:\Users\Admin\AppData\Local\Programs\Python\Python311\Lib\site-packages\httpx\_client.py", line 1719, in _send_single_request
    response = await transport.handle_async_request(request)
               ^^^^^^^^^^^^^^^^^^^^^^^^^^^^^^^^^^^^^^^^^^^^^
  File "C:\Users\Admin\AppData\Local\Programs\Python\Python311\Lib\site-packages\httpx\_transports\default.py", line 352, in handle_async_request
    with map_httpcore_exceptions():
  File "C:\Users\Admin\AppData\Local\Programs\Python\Python311\Lib\contextlib.py", line 158, in __exit__
    self.gen.throw(typ, value, traceback)
  File "C:\Users\Admin\AppData\Local\Programs\Python\Python311\Lib\site-packages\httpx\_transports\default.py", line 77, in map_httpcore_exceptions
    raise mapped_exc(message) from exc
httpx.ReadTimeout

The above exception was the direct cause of the following exception:

Traceback (most recent call last):
  File "F:\Crypto\Safe_Token_Bot\app\main.py", line 42, in main
    bot.run()
  File "F:\Crypto\Safe_Token_Bot\app\core\bot.py", line 567, in run
    self.application.run_polling(allowed_updates=Update.ALL_TYPES)
  File "C:\Users\Admin\AppData\Local\Programs\Python\Python311\Lib\site-packages\telegram\ext\_application.py", line 765, in run_polling
    return self.__run(
           ^^^^^^^^^^^
  File "C:\Users\Admin\AppData\Local\Programs\Python\Python311\Lib\site-packages\telegram\ext\_application.py", line 963, in __run
    loop.run_until_complete(self.updater.stop())  # type: ignore[union-attr]
    ^^^^^^^^^^^^^^^^^^^^^^^^^^^^^^^^^^^^^^^^^^^^
  File "C:\Users\Admin\AppData\Local\Programs\Python\Python311\Lib\asyncio\base_events.py", line 654, in run_until_complete
    return future.result()
           ^^^^^^^^^^^^^^^
  File "C:\Users\Admin\AppData\Local\Programs\Python\Python311\Lib\site-packages\telegram\ext\_updater.py", line 752, in stop
    await self._stop_polling()
  File "C:\Users\Admin\AppData\Local\Programs\Python\Python311\Lib\site-packages\telegram\ext\_updater.py", line 777, in _stop_polling
    await self.__polling_cleanup_cb()
  File "C:\Users\Admin\AppData\Local\Programs\Python\Python311\Lib\site-packages\telegram\ext\_updater.py", line 381, in _get_updates_cleanup
    await self.bot.get_updates(
  File "C:\Users\Admin\AppData\Local\Programs\Python\Python311\Lib\site-packages\telegram\ext\_extbot.py", line 553, in get_updates
    updates = await super().get_updates(
              ^^^^^^^^^^^^^^^^^^^^^^^^^^
  File "C:\Users\Admin\AppData\Local\Programs\Python\Python311\Lib\site-packages\telegram\_bot.py", line 394, in decorator
    result = await func(self, *args, **kwargs)  # skipcq: PYL-E1102
             ^^^^^^^^^^^^^^^^^^^^^^^^^^^^^^^^^
  File "C:\Users\Admin\AppData\Local\Programs\Python\Python311\Lib\site-packages\telegram\_bot.py", line 3542, in get_updates
    await self._post(
  File "C:\Users\Admin\AppData\Local\Programs\Python\Python311\Lib\site-packages\telegram\_bot.py", line 482, in _post
    return await self._do_post(
           ^^^^^^^^^^^^^^^^^^^^
  File "C:\Users\Admin\AppData\Local\Programs\Python\Python311\Lib\site-packages\telegram\ext\_extbot.py", line 335, in _do_post
    return await super()._do_post(
           ^^^^^^^^^^^^^^^^^^^^^^^
  File "C:\Users\Admin\AppData\Local\Programs\Python\Python311\Lib\site-packages\telegram\_bot.py", line 510, in _do_post
    return await request.post(
           ^^^^^^^^^^^^^^^^^^^
  File "C:\Users\Admin\AppData\Local\Programs\Python\Python311\Lib\site-packages\telegram\request\_baserequest.py", line 168, in post
    result = await self._request_wrapper(
             ^^^^^^^^^^^^^^^^^^^^^^^^^^^^
  File "C:\Users\Admin\AppData\Local\Programs\Python\Python311\Lib\site-packages\telegram\request\_baserequest.py", line 288, in _request_wrapper
    raise exc
  File "C:\Users\Admin\AppData\Local\Programs\Python\Python311\Lib\site-packages\telegram\request\_baserequest.py", line 278, in _request_wrapper
    code, payload = await self.do_request(
                    ^^^^^^^^^^^^^^^^^^^^^^
  File "C:\Users\Admin\AppData\Local\Programs\Python\Python311\Lib\site-packages\telegram\request\_httpxrequest.py", line 236, in do_request
    raise TimedOut from err
telegram.error.TimedOut: Timed out
2025-04-01 22:24:06 - bot - INFO - Starting Token Security Bot...
2025-04-01 22:37:21 - bot - ERROR - Fatal error: Timed out
Traceback (most recent call last):
  File "C:\Users\Admin\AppData\Local\Programs\Python\Python311\Lib\site-packages\anyio\streams\tls.py", line 140, in _call_sslobject_method
    result = func(*args)
             ^^^^^^^^^^^
  File "C:\Users\Admin\AppData\Local\Programs\Python\Python311\Lib\ssl.py", line 921, in read
    v = self._sslobj.read(len)
        ^^^^^^^^^^^^^^^^^^^^^^
ssl.SSLWantReadError: The operation did not complete (read) (_ssl.c:2580)

During handling of the above exception, another exception occurred:

Traceback (most recent call last):
  File "C:\Users\Admin\AppData\Local\Programs\Python\Python311\Lib\site-packages\anyio\_core\_tasks.py", line 115, in fail_after
    yield cancel_scope
  File "C:\Users\Admin\AppData\Local\Programs\Python\Python311\Lib\site-packages\httpcore\_backends\anyio.py", line 34, in read
    return await self._stream.receive(max_bytes=max_bytes)
           ^^^^^^^^^^^^^^^^^^^^^^^^^^^^^^^^^^^^^^^^^^^^^^^
  File "C:\Users\Admin\AppData\Local\Programs\Python\Python311\Lib\site-packages\anyio\streams\tls.py", line 204, in receive
    data = await self._call_sslobject_method(self._ssl_object.read, max_bytes)
           ^^^^^^^^^^^^^^^^^^^^^^^^^^^^^^^^^^^^^^^^^^^^^^^^^^^^^^^^^^^^^^^^^^^
  File "C:\Users\Admin\AppData\Local\Programs\Python\Python311\Lib\site-packages\anyio\streams\tls.py", line 147, in _call_sslobject_method
    data = await self.transport_stream.receive()
           ^^^^^^^^^^^^^^^^^^^^^^^^^^^^^^^^^^^^^
  File "C:\Users\Admin\AppData\Local\Programs\Python\Python311\Lib\site-packages\anyio\_backends\_asyncio.py", line 1246, in receive
    await self._protocol.read_event.wait()
  File "C:\Users\Admin\AppData\Local\Programs\Python\Python311\Lib\asyncio\locks.py", line 213, in wait
    await fut
asyncio.exceptions.CancelledError: Cancelled by cancel scope 2ad76328f90

During handling of the above exception, another exception occurred:

Traceback (most recent call last):
  File "C:\Users\Admin\AppData\Local\Programs\Python\Python311\Lib\site-packages\httpcore\_exceptions.py", line 10, in map_exceptions
    yield
  File "C:\Users\Admin\AppData\Local\Programs\Python\Python311\Lib\site-packages\httpcore\_backends\anyio.py", line 32, in read
    with anyio.fail_after(timeout):
  File "C:\Users\Admin\AppData\Local\Programs\Python\Python311\Lib\contextlib.py", line 158, in __exit__
    self.gen.throw(typ, value, traceback)
  File "C:\Users\Admin\AppData\Local\Programs\Python\Python311\Lib\site-packages\anyio\_core\_tasks.py", line 118, in fail_after
    raise TimeoutError
TimeoutError

The above exception was the direct cause of the following exception:

Traceback (most recent call last):
  File "C:\Users\Admin\AppData\Local\Programs\Python\Python311\Lib\site-packages\httpx\_transports\default.py", line 60, in map_httpcore_exceptions
    yield
  File "C:\Users\Admin\AppData\Local\Programs\Python\Python311\Lib\site-packages\httpx\_transports\default.py", line 353, in handle_async_request
    resp = await self._pool.handle_async_request(req)
           ^^^^^^^^^^^^^^^^^^^^^^^^^^^^^^^^^^^^^^^^^^
  File "C:\Users\Admin\AppData\Local\Programs\Python\Python311\Lib\site-packages\httpcore\_async\connection_pool.py", line 262, in handle_async_request
    raise exc
  File "C:\Users\Admin\AppData\Local\Programs\Python\Python311\Lib\site-packages\httpcore\_async\connection_pool.py", line 245, in handle_async_request
    response = await connection.handle_async_request(request)
               ^^^^^^^^^^^^^^^^^^^^^^^^^^^^^^^^^^^^^^^^^^^^^^
  File "C:\Users\Admin\AppData\Local\Programs\Python\Python311\Lib\site-packages\httpcore\_async\connection.py", line 96, in handle_async_request
    return await self._connection.handle_async_request(request)
           ^^^^^^^^^^^^^^^^^^^^^^^^^^^^^^^^^^^^^^^^^^^^^^^^^^^^
  File "C:\Users\Admin\AppData\Local\Programs\Python\Python311\Lib\site-packages\httpcore\_async\http11.py", line 121, in handle_async_request
    raise exc
  File "C:\Users\Admin\AppData\Local\Programs\Python\Python311\Lib\site-packages\httpcore\_async\http11.py", line 99, in handle_async_request
    ) = await self._receive_response_headers(**kwargs)
        ^^^^^^^^^^^^^^^^^^^^^^^^^^^^^^^^^^^^^^^^^^^^^^
  File "C:\Users\Admin\AppData\Local\Programs\Python\Python311\Lib\site-packages\httpcore\_async\http11.py", line 164, in _receive_response_headers
    event = await self._receive_event(timeout=timeout)
            ^^^^^^^^^^^^^^^^^^^^^^^^^^^^^^^^^^^^^^^^^^
  File "C:\Users\Admin\AppData\Local\Programs\Python\Python311\Lib\site-packages\httpcore\_async\http11.py", line 200, in _receive_event
    data = await self._network_stream.read(
           ^^^^^^^^^^^^^^^^^^^^^^^^^^^^^^^^
  File "C:\Users\Admin\AppData\Local\Programs\Python\Python311\Lib\site-packages\httpcore\_backends\anyio.py", line 31, in read
    with map_exceptions(exc_map):
  File "C:\Users\Admin\AppData\Local\Programs\Python\Python311\Lib\contextlib.py", line 158, in __exit__
    self.gen.throw(typ, value, traceback)
  File "C:\Users\Admin\AppData\Local\Programs\Python\Python311\Lib\site-packages\httpcore\_exceptions.py", line 14, in map_exceptions
    raise to_exc(exc) from exc
httpcore.ReadTimeout

The above exception was the direct cause of the following exception:

Traceback (most recent call last):
  File "C:\Users\Admin\AppData\Local\Programs\Python\Python311\Lib\site-packages\telegram\request\_httpxrequest.py", line 219, in do_request
    res = await self._client.request(
          ^^^^^^^^^^^^^^^^^^^^^^^^^^^
  File "C:\Users\Admin\AppData\Local\Programs\Python\Python311\Lib\site-packages\httpx\_client.py", line 1530, in request
    return await self.send(request, auth=auth, follow_redirects=follow_redirects)
           ^^^^^^^^^^^^^^^^^^^^^^^^^^^^^^^^^^^^^^^^^^^^^^^^^^^^^^^^^^^^^^^^^^^^^^
  File "C:\Users\Admin\AppData\Local\Programs\Python\Python311\Lib\site-packages\httpx\_client.py", line 1617, in send
    response = await self._send_handling_auth(
               ^^^^^^^^^^^^^^^^^^^^^^^^^^^^^^^
  File "C:\Users\Admin\AppData\Local\Programs\Python\Python311\Lib\site-packages\httpx\_client.py", line 1645, in _send_handling_auth
    response = await self._send_handling_redirects(
               ^^^^^^^^^^^^^^^^^^^^^^^^^^^^^^^^^^^^
  File "C:\Users\Admin\AppData\Local\Programs\Python\Python311\Lib\site-packages\httpx\_client.py", line 1682, in _send_handling_redirects
    response = await self._send_single_request(request)
               ^^^^^^^^^^^^^^^^^^^^^^^^^^^^^^^^^^^^^^^^
  File "C:\Users\Admin\AppData\Local\Programs\Python\Python311\Lib\site-packages\httpx\_client.py", line 1719, in _send_single_request
    response = await transport.handle_async_request(request)
               ^^^^^^^^^^^^^^^^^^^^^^^^^^^^^^^^^^^^^^^^^^^^^
  File "C:\Users\Admin\AppData\Local\Programs\Python\Python311\Lib\site-packages\httpx\_transports\default.py", line 352, in handle_async_request
    with map_httpcore_exceptions():
  File "C:\Users\Admin\AppData\Local\Programs\Python\Python311\Lib\contextlib.py", line 158, in __exit__
    self.gen.throw(typ, value, traceback)
  File "C:\Users\Admin\AppData\Local\Programs\Python\Python311\Lib\site-packages\httpx\_transports\default.py", line 77, in map_httpcore_exceptions
    raise mapped_exc(message) from exc
httpx.ReadTimeout

The above exception was the direct cause of the following exception:

Traceback (most recent call last):
  File "F:\Crypto\Safe_Token_Bot\app\main.py", line 42, in main
    bot.run()
  File "F:\Crypto\Safe_Token_Bot\app\core\bot.py", line 567, in run
    self.application.run_polling(allowed_updates=Update.ALL_TYPES)
  File "C:\Users\Admin\AppData\Local\Programs\Python\Python311\Lib\site-packages\telegram\ext\_application.py", line 765, in run_polling
    return self.__run(
           ^^^^^^^^^^^
  File "C:\Users\Admin\AppData\Local\Programs\Python\Python311\Lib\site-packages\telegram\ext\_application.py", line 963, in __run
    loop.run_until_complete(self.updater.stop())  # type: ignore[union-attr]
    ^^^^^^^^^^^^^^^^^^^^^^^^^^^^^^^^^^^^^^^^^^^^
  File "C:\Users\Admin\AppData\Local\Programs\Python\Python311\Lib\asyncio\base_events.py", line 654, in run_until_complete
    return future.result()
           ^^^^^^^^^^^^^^^
  File "C:\Users\Admin\AppData\Local\Programs\Python\Python311\Lib\site-packages\telegram\ext\_updater.py", line 752, in stop
    await self._stop_polling()
  File "C:\Users\Admin\AppData\Local\Programs\Python\Python311\Lib\site-packages\telegram\ext\_updater.py", line 777, in _stop_polling
    await self.__polling_cleanup_cb()
  File "C:\Users\Admin\AppData\Local\Programs\Python\Python311\Lib\site-packages\telegram\ext\_updater.py", line 381, in _get_updates_cleanup
    await self.bot.get_updates(
  File "C:\Users\Admin\AppData\Local\Programs\Python\Python311\Lib\site-packages\telegram\ext\_extbot.py", line 553, in get_updates
    updates = await super().get_updates(
              ^^^^^^^^^^^^^^^^^^^^^^^^^^
  File "C:\Users\Admin\AppData\Local\Programs\Python\Python311\Lib\site-packages\telegram\_bot.py", line 394, in decorator
    result = await func(self, *args, **kwargs)  # skipcq: PYL-E1102
             ^^^^^^^^^^^^^^^^^^^^^^^^^^^^^^^^^
  File "C:\Users\Admin\AppData\Local\Programs\Python\Python311\Lib\site-packages\telegram\_bot.py", line 3542, in get_updates
    await self._post(
  File "C:\Users\Admin\AppData\Local\Programs\Python\Python311\Lib\site-packages\telegram\_bot.py", line 482, in _post
    return await self._do_post(
           ^^^^^^^^^^^^^^^^^^^^
  File "C:\Users\Admin\AppData\Local\Programs\Python\Python311\Lib\site-packages\telegram\ext\_extbot.py", line 335, in _do_post
    return await super()._do_post(
           ^^^^^^^^^^^^^^^^^^^^^^^
  File "C:\Users\Admin\AppData\Local\Programs\Python\Python311\Lib\site-packages\telegram\_bot.py", line 510, in _do_post
    return await request.post(
           ^^^^^^^^^^^^^^^^^^^
  File "C:\Users\Admin\AppData\Local\Programs\Python\Python311\Lib\site-packages\telegram\request\_baserequest.py", line 168, in post
    result = await self._request_wrapper(
             ^^^^^^^^^^^^^^^^^^^^^^^^^^^^
  File "C:\Users\Admin\AppData\Local\Programs\Python\Python311\Lib\site-packages\telegram\request\_baserequest.py", line 288, in _request_wrapper
    raise exc
  File "C:\Users\Admin\AppData\Local\Programs\Python\Python311\Lib\site-packages\telegram\request\_baserequest.py", line 278, in _request_wrapper
    code, payload = await self.do_request(
                    ^^^^^^^^^^^^^^^^^^^^^^
  File "C:\Users\Admin\AppData\Local\Programs\Python\Python311\Lib\site-packages\telegram\request\_httpxrequest.py", line 236, in do_request
    raise TimedOut from err
telegram.error.TimedOut: Timed out
2025-04-01 22:37:38 - bot - INFO - Starting Token Security Bot...
